Workbook

Sheet Cook log
A1: Date | B1: Day | C1: Dish | D1: Notes
A2: 46153 | B2: =IF(A2="","",TEXT(A2,"ddd")) | C2: Taiwanese pork chop | D2: planned (week of 11 May 2026)
A3: 46153 | B3: =IF(A3="","",TEXT(A3,"ddd")) | C3: Fried rice with prawns | D3: planned (week of 11 May 2026)
A4: 46154 | B4: =IF(A4="","",TEXT(A4,"ddd")) | C4: Steamed pomfret | D4: planned (week of 11 May 2026)
A5: 46154 | B5: =IF(A5="","",TEXT(A5,"ddd")) | C5: Pork rib king | D5: planned (week of 11 May 2026)
A6: 46154 | B6: =IF(A6="","",TEXT(A6,"ddd")) | C6: Eggplant with minced pork | D6: planned (week of 11 May 2026)
A7: 46155 | B7: =IF(A7="","",TEXT(A7,"ddd")) | C7: Ee-fu mee | D7: planned (week of 11 May 2026)
A8: 46155 | B8: =IF(A8="","",TEXT(A8,"ddd")) | C8: HK style steamed seabass | D8: planned (week of 11 May 2026)
A9: 46156 | B9: =IF(A9="","",TEXT(A9,"ddd")) | C9: Steamed egg (ah gong style) | D9: planned (week of 11 May 2026)
A10: 46156 | B10: =IF(A10="","",TEXT(A10,"ddd")) | C10: Radish pork rib soup with dates | D10: planned (week of 11 May 2026)
A11: 46156 | B11: =IF(A11="","",TEXT(A11,"ddd")) | C11: Wasabi mayo prawns | D11: planned (week of 11 May 2026)
A12: 46157 | B12: =IF(A12="","",TEXT(A12,"ddd")) | C12: Chicken chop | D12: planned (week of 11 May 2026)
A13: 46157 | B13: =IF(A13="","",TEXT(A13,"ddd")) | C13: Mash potatoes | D13: planned (week of 11 May 2026)
... A295: 46318 | B295: =IF(A295="","",TEXT(A295,"ddd")) | C295: Steamed rice | D295: planned (week of 19 Oct 2026)
B296: =IF(A296="","",TEXT(A296,"ddd"))
B297: =IF(A297="","",TEXT(A297,"ddd"))
B298: =IF(A298="","",TEXT(A298,"ddd"))
B299: =IF(A299="","",TEXT(A299,"ddd"))
B300: =IF(A300="","",TEXT(A300,"ddd"))

Sheet Dish rotation
A1: Dish | B1: Category | C1: Last cooked | D1: Days since | E1: Cook count | F1: Cool-down (days) | G1: Status | H1: Notes
A2: Taiwanese pork chop | B2: Pork | C2: =IFERROR(IF(MAXIFS('Cook log'!A2:A1000,'Cook log'!C2:C1000,A2)=0,"",MAXIFS('Cook log'!A2:A1000,'Cook log'!C2:C1000,A2)),"") | D2: =IF(C2="","",TODAY()-C2) | E2: =COUNTIF('Cook log'!C2:C1000,A2) | F2: 21 | G2: =IF(C2="","Never cooked",IF(D2<F2,"Cooldown","Due"))
A3: Fried rice with prawns | B3: Prawn | C3: =IFERROR(IF(MAXIFS('Cook log'!A2:A1000,'Cook log'!C2:C1000,A3)=0,"",MAXIFS('Cook log'!A2:A1000,'Cook log'!C2:C1000,A3)),"") | D3: =IF(C3="","",TODAY()-C3) | E3: =COUNTIF('Cook log'!C2:C1000,A3) | F3: 14 | G3: =IF(C3="","Never cooked",IF(D3<F3,"Cooldown","Due"))
A4: Steamed pomfret | B4: Fish | C4: =IFERROR(IF(MAXIFS('Cook log'!A2:A1000,'Cook log'!C2:C1000,A4)=0,"",MAXIFS('Cook log'!A2:A1000,'Cook log'!C2:C1000,A4)),"") | D4: =IF(C4="","",TODAY()-C4) | E4: =COUNTIF('Cook log'!C2:C1000,A4) | F4: 21 | G4: =IF(C4="","Never cooked",IF(D4<F4,"Cooldown","Due"))
A5: Pork rib king | B5: Pork | C5: =IFERROR(IF(MAXIFS('Cook log'!A2:A1000,'Cook log'!C2:C1000,A5)=0,"",MAXIFS('Cook log'!A2:A1000,'Cook log'!C2:C1000,A5)),"") | D5: =IF(C5="","",TODAY()-C5) | E5: =COUNTIF('Cook log'!C2:C1000,A5) | F5: 21 | G5: =IF(C5="","Never cooked",IF(D5<F5,"Cooldown","Due")) | H5: recipes/pork-rib-king.md - ingredients only, method in the video (0WXGuOQq_xU). x1.5 for 5 pax
A6: Eggplant with minced pork | B6: Pork | C6: =IFERROR(IF(MAXIFS('Cook log'!A2:A1000,'Cook log'!C2:C1000,A6)=0,"",MAXIFS('Cook log'!A2:A1000,'Cook log'!C2:C1000,A6)),"") | D6: =IF(C6="","",TODAY()-C6) | E6: =COUNTIF('Cook log'!C2:C1000,A6) | F6: 21 | G6: =IF(C6="","Never cooked",IF(D6<F6,"Cooldown","Due"))
A7: Ee-fu mee | B7: Noodle | C7: =IFERROR(IF(MAXIFS('Cook log'!A2:A1000,'Cook log'!C2:C1000,A7)=0,"",MAXIFS('Cook log'!A2:A1000,'Cook log'!C2:C1000,A7)),"") | D7: =IF(C7="","",TODAY()-C7) | E7: =COUNTIF('Cook log'!C2:C1000,A7) | F7: 21 | G7: =IF(C7="","Never cooked",IF(D7<F7,"Cooldown","Due"))
A8: HK style steamed seabass | B8: Fish | C8: =IFERROR(IF(MAXIFS('Cook log'!A2:A1000,'Cook log'!C2:C1000,A8)=0,"",MAXIFS('Cook log'!A2:A1000,'Cook log'!C2:C1000,A8)),"") | D8: =IF(C8="","",TODAY()-C8) | E8: =COUNTIF('Cook log'!C2:C1000,A8) | F8: 21 | G8: =IF(C8="","Never cooked",IF(D8<F8,"Cooldown","Due"))
A9: Steamed egg (ah gong style) | B9: Egg | C9: =IFERROR(IF(MAXIFS('Cook log'!A2:A1000,'Cook log'!C2:C1000,A9)=0,"",MAXIFS('Cook log'!A2:A1000,'Cook log'!C2:C1000,A9)),"") | D9: =IF(C9="","",TODAY()-C9) | E9: =COUNTIF('Cook log'!C2:C1000,A9) | F9: 14 | G9: =IF(C9="","Never cooked",IF(D9<F9,"Cooldown","Due"))
A10: Radish pork rib soup with dates | B10: Soup | C10: =IFERROR(IF(MAXIFS('Cook log'!A2:A1000,'Cook log'!C2:C1000,A10)=0,"",MAXIFS('Cook log'!A2:A1000,'Cook log'!C2:C1000,A10)),"") | D10: =IF(C10="","",TODAY()-C10) | E10: =COUNTIF('Cook log'!C2:C1000,A10) | F10: 21 | G10: =IF(C10="","Never cooked",IF(D10<F10,"Cooldown","Due"))
A11: Wasabi mayo prawns | B11: Prawn | C11: =IFERROR(IF(MAXIFS('Cook log'!A2:A1000,'Cook log'!C2:C1000,A11)=0,"",MAXIFS('Cook log'!A2:A1000,'Cook log'!C2:C1000,A11)),"") | D11: =IF(C11="","",TODAY()-C11) | E11: =COUNTIF('Cook log'!C2:C1000,A11) | F11: 21 | G11: =IF(C11="","Never cooked",IF(D11<F11,"Cooldown","Due"))
A12: Chicken chop | B12: Chicken | C12: =IFERROR(IF(MAXIFS('Cook log'!A2:A1000,'Cook log'!C2:C1000,A12)=0,"",MAXIFS('Cook log'!A2:A1000,'Cook log'!C2:C1000,A12)),"") | D12: =IF(C12="","",TODAY()-C12) | E12: =COUNTIF('Cook log'!C2:C1000,A12) | F12: 21 | G12: =IF(C12="","Never cooked",IF(D12<F12,"Cooldown","Due"))
A13: Mash potatoes | B13: Side | C13: =IFERROR(IF(MAXIFS('Cook log'!A2:A1000,'Cook log'!C2:C1000,A13)=0,"",MAXIFS('Cook log'!A2:A1000,'Cook log'!C2:C1000,A13)),"") | D13: =IF(C13="","",TODAY()-C13) | E13: =COUNTIF('Cook log'!C2:C1000,A13) | F13: 21 | G13: =IF(C13="","Never cooked",IF(D13<F13,"Cooldown","Due"))
A14: Roasted vegetables (oven) | B14: Vegetable | C14: =IFERROR(IF(MAXIFS('Cook log'!A2:A1000,'Cook log'!C2:C1000,A14)=0,"",MAXIFS('Cook log'!A2:A1000,'Cook log'!C2:C1000,A14)),"") | D14: =IF(C14="","",TODAY()-C14) | E14: =COUNTIF('Cook log'!C2:C1000,A14) | F14: 21 | G14: =IF(C14="","Never cooked",IF(D14<F14,"Cooldown","Due")) | H14: recipes/roasted-vegetables.md - ingredients only; x1.25 for 5 pax; potato wedges left out when roast potatoes are served
A15: Sticky pork belly | B15: Pork | C15: =IFERROR(IF(MAXIFS('Cook log'!A2:A1000,'Cook log'!C2:C1000,A15)=0,"",MAXIFS('Cook log'!A2:A1000,'Cook log'!C2:C1000,A15)),"") | D15: =IF(C15="","",TODAY()-C15) | E15: =COUNTIF('Cook log'!C2:C1000,A15) | F15: 21 | G15: =IF(C15="","Never cooked",IF(D15<F15,"Cooldown","Due"))
A16: Taiwanese braised pork rice | B16: Pork | C16: =IFERROR(IF(MAXIFS('Cook log'!A2:A1000,'Cook log'!C2:C1000,A16)=0,"",MAXIFS('Cook log'!A2:A1000,'Cook log'!C2:C1000,A16)),"") | D16: =IF(C16="","",TODAY()-C16) | E16: =COUNTIF('Cook log'!C2:C1000,A16) | F16: 28 | G16: =IF(C16="","Never cooked",IF(D16<F16,"Cooldown","Due")) | H16: recipes/taiwanese-braised-pork-rice.md - ingredients only, method in the video (hqcVtqGoRG0)
A17: Steamed fish paste with minced meat | B17: Fish | C17: =IFERROR(IF(MAXIFS('Cook log'!A2:A1000,'Cook log'!C2:C1000,A17)=0,"",MAXIFS('Cook log'!A2:A1000,'Cook log'!C2:C1000,A17)),"") | D17: =IF(C17="","",TODAY()-C17) | E17: =COUNTIF('Cook log'!C2:C1000,A17) | F17: 28 | G17: =IF(C17="","Never cooked",IF(D17<F17,"Cooldown","Due")) | H17: recipes/steamed-fish-paste-with-minced-pork.md - user's own recipe, revised 17 Oct 2026: pork 1/3 and garlic paste 1/4-1/3 of the fish paste by volume; oil on top; steam 15 min. Never cooked
A18: Steamed tofu with minced pork | B18: Egg | C18: =IFERROR(IF(MAXIFS('Cook log'!A2:A1000,'Cook log'!C2:C1000,A18)=0,"",MAXIFS('Cook log'!A2:A1000,'Cook log'!C2:C1000,A18)),"") | D18: =IF(C18="","",TODAY()-C18) | E18: =COUNTIF('Cook log'!C2:C1000,A18) | F18: 21 | G18: =IF(C18="","Never cooked",IF(D18<F18,"Cooldown","Due"))
A19: Ah gong gai fan | B19: Chicken | C19: =IFERROR(IF(MAXIFS('Cook log'!A2:A1000,'Cook log'!C2:C1000,A19)=0,"",MAXIFS('Cook log'!A2:A1000,'Cook log'!C2:C1000,A19)),"") | D19: =IF(C19="","",TODAY()-C19) | E19: =COUNTIF('Cook log'!C2:C1000,A19) | F19: 21 | G19: =IF(C19="","Never cooked",IF(D19<F19,"Cooldown","Due"))
A20: Sesame chicken mee sua | B20: Chicken | C20: =IFERROR(IF(MAXIFS('Cook log'!A2:A1000,'Cook log'!C2:C1000,A20)=0,"",MAXIFS('Cook log'!A2:A1000,'Cook log'!C2:C1000,A20)),"") | D20: =IF(C20="","",TODAY()-C20) | E20: =COUNTIF('Cook log'!C2:C1000,A20) | F20: 21 | G20: =IF(C20="","Never cooked",IF(D20<F20,"Cooldown","Due"))
A21: Teriyaki chicken cutlet | B21: Chicken | C21: =IFERROR(IF(MAXIFS('Cook log'!A2:A1000,'Cook log'!C2:C1000,A21)=0,"",MAXIFS('Cook log'!A2:A1000,'Cook log'!C2:C1000,A21)),"") | D21: =IF(C21="","",TODAY()-C21) | E21: =COUNTIF('Cook log'!C2:C1000,A21) | F21: 28 | G21: =IF(C21="","Never cooked",IF(D21<F21,"Cooldown","Due"))
A22: Macau Portuguese chicken rice | B22: Chicken | C22: =IFERROR(IF(MAXIFS('Cook log'!A2:A1000,'Cook log'!C2:C1000,A22)=0,"",MAXIFS('Cook log'!A2:A1000,'Cook log'!C2:C1000,A22)),"") | D22: =IF(C22="","",TODAY()-C22) | E22: =COUNTIF('Cook log'!C2:C1000,A22) | F22: 35 | G22: =IF(C22="","Never cooked",IF(D22<F22,"Cooldown","Due"))
A23: Claypot chicken rice | B23: Chicken | C23: =IFERROR(IF(MAXIFS('Cook log'!A2:A1000,'Cook log'!C2:C1000,A23)=0,"",MAXIFS('Cook log'!A2:A1000,'Cook log'!C2:C1000,A23)),"") | D23: =IF(C23="","",TODAY()-C23) | E23: =COUNTIF('Cook log'!C2:C1000,A23) | F23: 28 | G23: =IF(C23="","Never cooked",IF(D23<F23,"Cooldown","Due"))
A24: Baked chicken wings | B24: Chicken | C24: =IFERROR(IF(MAXIFS('Cook log'!A2:A1000,'Cook log'!C2:C1000,A24)=0,"",MAXIFS('Cook log'!A2:A1000,'Cook log'!C2:C1000,A24)),"") | D24: =IF(C24="","",TODAY()-C24) | E24: =COUNTIF('Cook log'!C2:C1000,A24) | F24: 21 | G24: =IF(C24="","Never cooked",IF(D24<F24,"Cooldown","Due")) | H24: recipes/soy-and-oyster-sauce-wings.md - oven method; individually frozen mid wings, x0.6 marinade. Never cooked
A25: Steamed baby threadfin | B25: Fish | C25: =IFERROR(IF(MAXIFS('Cook log'!A2:A1000,'Cook log'!C2:C1000,A25)=0,"",MAXIFS('Cook log'!A2:A1000,'Cook log'!C2:C1000,A25)),"") | D25: =IF(C25="","",TODAY()-C25) | E25: =COUNTIF('Cook log'!C2:C1000,A25) | F25: 21 | G25: =IF(C25="","Never cooked",IF(D25<F25,"Cooldown","Due"))
A26: Salmon kabayaki | B26: Fish | C26: =IFERROR(IF(MAXIFS('Cook log'!A2:A1000,'Cook log'!C2:C1000,A26)=0,"",MAXIFS('Cook log'!A2:A1000,'Cook log'!C2:C1000,A26)),"") | D26: =IF(C26="","",TODAY()-C26) | E26: =COUNTIF('Cook log'!C2:C1000,A26) | F26: 28 | G26: =IF(C26="","Never cooked",IF(D26<F26,"Cooldown","Due"))
A27: Lemon butter salmon | B27: Fish | C27: =IFERROR(IF(MAXIFS('Cook log'!A2:A1000,'Cook log'!C2:C1000,A27)=0,"",MAXIFS('Cook log'!A2:A1000,'Cook log'!C2:C1000,A27)),"") | D27: =IF(C27="","",TODAY()-C27) | E27: =COUNTIF('Cook log'!C2:C1000,A27) | F27: 28 | G27: =IF(C27="","Never cooked",IF(D27<F27,"Cooldown","Due"))
A28: Assam fish | B28: Fish | C28: =IFERROR(IF(MAXIFS('Cook log'!A2:A1000,'Cook log'!C2:C1000,A28)=0,"",MAXIFS('Cook log'!A2:A1000,'Cook log'!C2:C1000,A28)),"") | D28: =IF(C28="","",TODAY()-C28) | E28: =COUNTIF('Cook log'!C2:C1000,A28) | F28: 28 | G28: =IF(C28="","Never cooked",IF(D28<F28,"Cooldown","Due"))
A29: Thai style steamed seabass | B29: Fish | C29: =IFERROR(IF(MAXIFS('Cook log'!A2:A1000,'Cook log'!C2:C1000,A29)=0,"",MAXIFS('Cook log'!A2:A1000,'Cook log'!C2:C1000,A29)),"") | D29: =IF(C29="","",TODAY()-C29) | E29: =COUNTIF('Cook log'!C2:C1000,A29) | F29: 28 | G29: =IF(C29="","Never cooked",IF(D29<F29,"Cooldown","Due")) | H29: recipes/thai-style-steamed-fish.md - ingredients only, method in the video (-2hNdMmJogU); one 700g fish, chillies cut to 4-5
A30: Fish soup | B30: Fish | C30: =IFERROR(IF(MAXIFS('Cook log'!A2:A1000,'Cook log'!C2:C1000,A30)=0,"",MAXIFS('Cook log'!A2:A1000,'Cook log'!C2:C1000,A30)),"") | D30: =IF(C30="","",TODAY()-C30) | E30: =COUNTIF('Cook log'!C2:C1000,A30) | F30: 21 | G30: =IF(C30="","Never cooked",IF(D30<F30,"Cooldown","Due"))
A31: Prawn omelette | B31: Prawn | C31: =IFERROR(IF(MAXIFS('Cook log'!A2:A1000,'Cook log'!C2:C1000,A31)=0,"",MAXIFS('Cook log'!A2:A1000,'Cook log'!C2:C1000,A31)),"") | D31: =IF(C31="","",TODAY()-C31) | E31: =COUNTIF('Cook log'!C2:C1000,A31) | F31: 21 | G31: =IF(C31="","Never cooked",IF(D31<F31,"Cooldown","Due"))
A32: Pineapple fried rice | B32: Rice | C32: =IFERROR(IF(MAXIFS('Cook log'!A2:A1000,'Cook log'!C2:C1000,A32)=0,"",MAXIFS('Cook log'!A2:A1000,'Cook log'!C2:C1000,A32)),"") | D32: =IF(C32="","",TODAY()-C32) | E32: =COUNTIF('Cook log'!C2:C1000,A32) | F32: 28 | G32: =IF(C32="","Never cooked",IF(D32<F32,"Cooldown","Due"))
A33: Egg fried rice | B33: Rice | C33: =IFERROR(IF(MAXIFS('Cook log'!A2:A1000,'Cook log'!C2:C1000,A33)=0,"",MAXIFS('Cook log'!A2:A1000,'Cook log'!C2:C1000,A33)),"") | D33: =IF(C33="","",TODAY()-C33) | E33: =COUNTIF('Cook log'!C2:C1000,A33) | F33: 14 | G33: =IF(C33="","Never cooked",IF(D33<F33,"Cooldown","Due"))
A34: Yam rice | B34: Rice | C34: =IFERROR(IF(MAXIFS('Cook log'!A2:A1000,'Cook log'!C2:C1000,A34)=0,"",MAXIFS('Cook log'!A2:A1000,'Cook log'!C2:C1000,A34)),"") | D34: =IF(C34="","",TODAY()-C34) | E34: =COUNTIF('Cook log'!C2:C1000,A34) | F34: 28 | G34: =IF(C34="","Never cooked",IF(D34<F34,"Cooldown","Due")) | H34: recipes/yam-rice.md - pork belly version (user, 17 Oct 2026), x1.6. Never cooked
A35: Hokkien kiam png | B35: Rice | C35: =IFERROR(IF(MAXIFS('Cook log'!A2:A1000,'Cook log'!C2:C1000,A35)=0,"",MAXIFS('Cook log'!A2:A1000,'Cook log'!C2:C1000,A35)),"") | D35: =IF(C35="","",TODAY()-C35) | E35: =COUNTIF('Cook log'!C2:C1000,A35) | F35: 28 | G35: =IF(C35="","Never cooked",IF(D35<F35,"Cooldown","Due"))
A36: Stir fried bee hoon | B36: Noodle | C36: =IFERROR(IF(MAXIFS('Cook log'!A2:A1000,'Cook log'!C2:C1000,A36)=0,"",MAXIFS('Cook log'!A2:A1000,'Cook log'!C2:C1000,A36)),"") | D36: =IF(C36="","",TODAY()-C36) | E36: =COUNTIF('Cook log'!C2:C1000,A36) | F36: 14 | G36: =IF(C36="","Never cooked",IF(D36<F36,"Cooldown","Due"))
A37: Fried udon | B37: Noodle | C37: =IFERROR(IF(MAXIFS('Cook log'!A2:A1000,'Cook log'!C2:C1000,A37)=0,"",MAXIFS('Cook log'!A2:A1000,'Cook log'!C2:C1000,A37)),"") | D37: =IF(C37="","",TODAY()-C37) | E37: =COUNTIF('Cook log'!C2:C1000,A37) | F37: 21 | G37: =IF(C37="","Never cooked",IF(D37<F37,"Cooldown","Due"))
A38: Hong Kong style fried noodles | B38: Noodle | C38: =IFERROR(IF(MAXIFS('Cook log'!A2:A1000,'Cook log'!C2:C1000,A38)=0,"",MAXIFS('Cook log'!A2:A1000,'Cook log'!C2:C1000,A38)),"") | D38: =IF(C38="","",TODAY()-C38) | E38: =COUNTIF('Cook log'!C2:C1000,A38) | F38: 21 | G38: =IF(C38="","Never cooked",IF(D38<F38,"Cooldown","Due"))
A39: Pork noodle soup | B39: Noodle | C39: =IFERROR(IF(MAXIFS('Cook log'!A2:A1000,'Cook log'!C2:C1000,A39)=0,"",MAXIFS('Cook log'!A2:A1000,'Cook log'!C2:C1000,A39)),"") | D39: =IF(C39="","",TODAY()-C39) | E39: =COUNTIF('Cook log'!C2:C1000,A39) | F39: 21 | G39: =IF(C39="","Never cooked",IF(D39<F39,"Cooldown","Due"))
A40: Ah gong fried prawn noodle | B40: Noodle | C40: =IFERROR(IF(MAXIFS('Cook log'!A2:A1000,'Cook log'!C2:C1000,A40)=0,"",MAXIFS('Cook log'!A2:A1000,'Cook log'!C2:C1000,A40)),"") | D40: =IF(C40="","",TODAY()-C40) | E40: =COUNTIF('Cook log'!C2:C1000,A40) | F40: 28 | G40: =IF(C40="","Never cooked",IF(D40<F40,"Cooldown","Due"))
...

Sheet Reference
A1: Categories
A2: Beef
A3: Chicken
A4: Egg
A5: Fish
A6: Noodle
A7: Other
A8: Pork
A9: Prawn
A10: Rice
A11: Side
A12: Soup
... A14: Western
